<sdf version="1.6">
    <model name="x3">
        <pose>0 0 0 0 0 0</pose>
        <link name="X3/base_link">
            <pose frame="">0 0 0 0 0 0</pose>
            <inertial>
            <pose frame="">0.00 0.00 0 0 0 0</pose>
            <mass>1.0</mass>
            <inertia>
                <ixx>0.02</ixx>
                <ixy>0</ixy>
                <ixz>0</ixz>
                <iyy>0.02</iyy>
                <iyz>0</iyz>
                <izz>0.02</izz>
            </inertia>
            </inertial>
            <collision name="X3/base_link_inertia_collision">
            <pose frame="">0 0 0 0 0.0 0</pose>
            <geometry>
                <box>
                <size>0.4 0.4 0.4</size>
                </box>
            </geometry>
            </collision>

            <visual name="X3/base_link_inertia_visual">
            <pose frame="">0 0 0 0 0.0 0</pose>
            <geometry>
                <box>
                <size>0.4 0.4 0.4</size>
                </box>
            </geometry>
            <transparency>0.5</transparency>
            </visual>
        </link>

        <!--
        <joint name="fixed_base_joint" type="ball">
            <parent>world</parent>
            <child>X3/base_link</child>
        </joint>
        -->


        <link name="X3/rotor_0">
            <pose frame="X3/base_link">0.1 -0.1 0.1 2.20271  -0.21293 -0.415283</pose>
            <inertial>
                <pose frame="">0 0 0 0 -0 0</pose>
                <mass>0.01</mass>
                <inertia>
                    <ixx>1.0e-06</ixx>
                    <ixy>0</ixy>
                    <ixz>0</ixz>
                    <iyy>1.0e-06</iyy>
                    <iyz>0</iyz>
                    <izz>1.0e-06</izz>
                </inertia>
            </inertial>
            <visual name="X3/rotor_0_visual">
                <pose frame="">0 0 0 0 0 0</pose>
                <geometry>
                    <mesh>
                        <scale>0.06 0.06 0.06</scale>
                        <uri>https://fuel.gazebosim.org/1.0/openrobotics/models/x3 uav/4/files/meshes/propeller_ccw.dae</uri>
                    </mesh>
                </geometry>
                <material>
                    <script>
                        <name>Gazebo/Green</name>
                        <uri>file://media/materials/scripts/gazebo.material</uri>
                    </script>
                </material>
            </visual>
            <gravity>1</gravity>
            <velocity_decay/>
        </link>
        <joint name="X3/rotor_0_joint" type="revolute">
            <child>X3/rotor_0</child>
            <parent>X3/base_link</parent>
            <axis>
                <xyz>-0.211325 -0.788675  -0.57735</xyz>
                <limit>
                <lower>-1e+16</lower>
                <upper>1e+16</upper>
                </limit>
                <dynamics>
                <spring_reference>0</spring_reference>
                <spring_stiffness>0</spring_stiffness>
                </dynamics>
                <use_parent_model_frame>1</use_parent_model_frame>
            </axis>
        </joint>





        
        <link name="X3/rotor_1">
            <pose frame="X3/base_link">-0.1 -0.1 0.1 0.350879 0.908651 0.172719</pose>
            <inertial>
                <pose frame="">0 0 0 0 -0 0</pose>
                <mass>0.01</mass>
                <inertia>
                    <ixx>1.0e-06</ixx>
                    <ixy>0</ixy>
                    <ixz>0</ixz>
                    <iyy>1.0e-06</iyy>
                    <iyz>0</iyz>
                    <izz>1.0e-06</izz>
                </inertia>
            </inertial>
            <visual name="X3/rotor_1_visual">
                <pose frame="">0 0 0 0 0 0</pose>
                <geometry>
                    <mesh>
                        <scale>0.06 0.06 0.06</scale>
                        <uri>https://fuel.gazebosim.org/1.0/openrobotics/models/x3 uav/4/files/meshes/propeller_cw.dae</uri>
                    </mesh>
                </geometry>
                <material>
                    <script>
                        <name>Gazebo/Green</name>
                        <uri>file://media/materials/scripts/gazebo.material</uri>
                    </script>
                </material>
            </visual>
            <gravity>1</gravity>
            <velocity_decay/>
        </link>
        <joint name="X3/rotor_1_joint" type="revolute">
            <child>X3/rotor_1</child>
            <parent>X3/base_link</parent>
            <axis>
                <xyz>0.788675 -0.211325   0.57735</xyz>
                <limit>
                <lower>-1e+16</lower>
                <upper>1e+16</upper>
                </limit>
                <dynamics>
                <spring_reference>0</spring_reference>
                <spring_stiffness>0</spring_stiffness>
                </dynamics>
                <use_parent_model_frame>1</use_parent_model_frame>
            </axis>
        </joint>




       <link name="X3/rotor_2">
            <pose frame="X3/base_link">0.1 -0.1 -0.1 -2.20271   0.21293 -0.415283</pose>
            <inertial>
                <pose frame="">0 0 0 0 -0 0</pose>
                <mass>0.01</mass>
                <inertia>
                    <ixx>1.0e-06</ixx>
                    <ixy>0</ixy>
                    <ixz>0</ixz>
                    <iyy>1.0e-06</iyy>
                    <iyz>0</iyz>
                    <izz>1.0e-06</izz>
                </inertia>
            </inertial>
            <visual name="X3/rotor_2_visual">
                <pose frame="">0 0 0 0 0 0</pose>
                <geometry>
                    <mesh>
                        <scale>0.06 0.06 0.06</scale>
                        <uri>https://fuel.gazebosim.org/1.0/openrobotics/models/x3 uav/4/files/meshes/propeller_ccw.dae</uri>
                    </mesh>
                </geometry>
                <material>
                    <script>
                        <name>Gazebo/Green</name>
                        <uri>file://media/materials/scripts/gazebo.material</uri>
                    </script>
                </material>
            </visual>
            <gravity>1</gravity>
            <velocity_decay/>
        </link>
        <joint name="X3/rotor_2_joint" type="revolute">
            <child>X3/rotor_2</child>
            <parent>X3/base_link</parent>
            <axis>
                <xyz>0.211325 0.788675 -0.57735</xyz>
                <limit>
                <lower>-1e+16</lower>
                <upper>1e+16</upper>
                </limit>
                <dynamics>
                <spring_reference>0</spring_reference>
                <spring_stiffness>0</spring_stiffness>
                </dynamics>
                <use_parent_model_frame>1</use_parent_model_frame>
            </axis>
        </joint>



        <link name="X3/rotor_3">
            <pose frame="X3/base_link">-0.1 -0.1 -0.1 -0.350879 -0.908651  0.172719</pose>
            <inertial>
                <pose frame="">0 0 0 0 -0 0</pose>
                <mass>0.01</mass>
                <inertia>
                    <ixx>1.0e-06</ixx>
                    <ixy>0</ixy>
                    <ixz>0</ixz>
                    <iyy>1.0e-06</iyy>
                    <iyz>0</iyz>
                    <izz>1.0e-06</izz>
                </inertia>
            </inertial>
            <visual name="X3/rotor_3_visual">
                <pose frame="">0 0 0 0 0 0</pose>​

                <geometry>
                    <mesh>
                        <scale>0.06 0.06 0.06</scale>
                        <uri>https://fuel.gazebosim.org/1.0/openrobotics/models/x3 uav/4/files/meshes/propeller_ccw.dae</uri>
                    </mesh>
                </geometry>
                <material>
                    <script>
                        <name>Gazebo/Green</name>
                        <uri>file://media/materials/scripts/gazebo.material</uri>
                    </script>
                </material>
            </visual>
            <gravity>1</gravity>
            <velocity_decay/>
        </link>
        <joint name="X3/rotor_3_joint" type="revolute">
            <child>X3/rotor_3</child>
            <parent>X3/base_link</parent>
            <axis>
                <xyz>-0.788675  0.211325   0.57735</xyz>
                <limit>
                <lower>-1e+16</lower>
                <upper>1e+16</upper>
                </limit>
                <dynamics>
                <spring_reference>0</spring_reference>
                <spring_stiffness>0</spring_stiffness>
                </dynamics>
                <use_parent_model_frame>1</use_parent_model_frame>
            </axis>
        </joint>



        <link name="X3/rotor_4">
            <pose frame="X3/base_link">0.1 0.1 -0.1 0.350879 0.908651 0.172719</pose>
            <inertial>
                <pose frame="">0 0 0 0 -0 0</pose>
                <mass>0.01</mass>
                <inertia>
                    <ixx>1.0e-06</ixx>
                    <ixy>0</ixy>
                    <ixz>0</ixz>
                    <iyy>1.0e-06</iyy>
                    <iyz>0</iyz>
                    <izz>1.0e-06</izz>
                </inertia>
            </inertial>
            <visual name="X3/rotor_4_visual">
                <pose frame="">0 0 0 0 0 0</pose>
                <geometry>
                    <mesh>
                        <scale>0.06 0.06 0.06</scale>
                        <uri>https://fuel.gazebosim.org/1.0/openrobotics/models/x3 uav/4/files/meshes/propeller_ccw.dae</uri>
                    </mesh>
                </geometry>
                <material>
                    <script>
                        <name>Gazebo/Green</name>
                        <uri>file://media/materials/scripts/gazebo.material</uri>
                    </script>
                </material>
            </visual>
            <gravity>1</gravity>
            <velocity_decay/>
        </link>
        <joint name="X3/rotor_4_joint" type="revolute">
            <child>X3/rotor_4</child>
            <parent>X3/base_link</parent>
            <axis>
                <xyz>0.788675 -0.211325 0.57735</xyz>
                <limit>
                <lower>-1e+16</lower>
                <upper>1e+16</upper>
                </limit>
                <dynamics>
                <spring_reference>0</spring_reference>
                <spring_stiffness>0</spring_stiffness>
                </dynamics>
                <use_parent_model_frame>1</use_parent_model_frame>
            </axis>
        </joint>



        <link name="X3/rotor_5">
            <pose frame="X3/base_link">-0.1 0.1 -0.1 2.20271 -0.21293 -0.415283</pose>
            <inertial>
                <pose frame="">0 0 0 0 -0 0</pose>
                <mass>0.01</mass>
                <inertia>
                    <ixx>1.0e-06</ixx>
                    <ixy>0</ixy>
                    <ixz>0</ixz>
                    <iyy>1.0e-06</iyy>
                    <iyz>0</iyz>
                    <izz>1.0e-06</izz>
                </inertia>
            </inertial>
            <visual name="X3/rotor_5_visual">
                <pose frame="">0 0 0 0 0 0</pose>
                <geometry>
                    <mesh>
                        <scale>0.06 0.06 0.06</scale>
                        <uri>https://fuel.gazebosim.org/1.0/openrobotics/models/x3 uav/4/files/meshes/propeller_cw.dae</uri>
                    </mesh>
                </geometry>
                <material>
                    <script>
                        <name>Gazebo/Green</name>
                        <uri>file://media/materials/scripts/gazebo.material</uri>
                    </script>
                </material>
            </visual>
            <gravity>1</gravity>
            <velocity_decay/>
        </link>
        <joint name="X3/rotor_5_joint" type="revolute">
            <child>X3/rotor_5</child>
            <parent>X3/base_link</parent>
            <axis>
                <xyz>-0.211325 -0.788675  -0.57735</xyz>
                <limit>
                <lower>-1e+16</lower>
                <upper>1e+16</upper>
                </limit>
                <dynamics>
                <spring_reference>0</spring_reference>
                <spring_stiffness>0</spring_stiffness>
                </dynamics>
                <use_parent_model_frame>1</use_parent_model_frame>
            </axis>
        </joint>





        <link name="X3/rotor_6"> 
            <pose frame="X3/base_link">0.1 0.1 0.1 -0.350879 -0.908651  0.172719</pose>
            <inertial>
                <pose frame="">0 0 0 0 -0 0</pose>
                <mass>0.01</mass>
                <inertia>
                    <ixx>1.0e-06</ixx>
                    <ixy>0</ixy>
                    <ixz>0</ixz>
                    <iyy>1.0e-06</iyy>
                    <iyz>0</iyz>
                    <izz>1.0e-06</izz>
                </inertia>
            </inertial>
            <visual name="X3/rotor_6_visual">
                <pose frame="">0 0 0 0 0 0</pose>
                <geometry>
                    <mesh>
                        <scale>0.06 0.06 0.06</scale>
                        <uri>https://fuel.gazebosim.org/1.0/openrobotics/models/x3 uav/4/files/meshes/propeller_cw.dae</uri>
                    </mesh>
                </geometry>
                <material>
                    <script>
                        <name>Gazebo/Green</name>
                        <uri>file://media/materials/scripts/gazebo.material</uri>
                    </script>
                </material>
            </visual>
            <gravity>1</gravity>
            <velocity_decay/>
        </link>
        <joint name="X3/rotor_6_joint" type="revolute">
            <child>X3/rotor_6</child>
            <parent>X3/base_link</parent>
            <axis>
                <xyz>-0.788675  0.211325   0.57735</xyz>
                <limit>
                <lower>-1e+16</lower>
                <upper>1e+16</upper>
                </limit>
                <dynamics>
                <spring_reference>0</spring_reference>
                <spring_stiffness>0</spring_stiffness>
                </dynamics>
                <use_parent_model_frame>1</use_parent_model_frame>
            </axis>
        </joint>


        <link name="X3/rotor_7"> 
            <pose frame="X3/base_link">-0.1 0.1 0.1 -2.20271 0.21293 -0.415283</pose>
            <inertial>
                <pose frame="">0 0 0 0 -0 0</pose>
                <mass>0.01</mass>
                <inertia>
                    <ixx>1.0e-06</ixx>
                    <ixy>0</ixy>
                    <ixz>0</ixz>
                    <iyy>1.0e-06</iyy>
                    <iyz>0</iyz>
                    <izz>1.0e-06</izz>
                </inertia>
            </inertial>
            <visual name="X3/rotor_7_visual">
                <pose frame="">0 0 0 0 0 0</pose>
                <geometry>
                    <mesh>
                        <scale>0.06 0.06 0.06</scale>
                        <uri>https://fuel.gazebosim.org/1.0/openrobotics/models/x3 uav/4/files/meshes/propeller_ccw.dae</uri>
                    </mesh>
                </geometry>
                <material>
                    <script>
                        <name>Gazebo/Green</name>
                        <uri>file://media/materials/scripts/gazebo.material</uri>
                    </script>
                </material>
            </visual>
            <gravity>1</gravity>
            <velocity_decay/>
        </link>
        <joint name="X3/rotor_7_joint" type="revolute">
            <child>X3/rotor_7</child>
            <parent>X3/base_link</parent>
            <axis>
                <xyz>0.211325 0.788675 -0.57735</xyz>
                <limit>
                <lower>-1e+16</lower>
                <upper>1e+16</upper>
                </limit>
                <dynamics>
                <spring_reference>0</spring_reference>
                <spring_stiffness>0</spring_stiffness>
                </dynamics>
                <use_parent_model_frame>1</use_parent_model_frame>
            </axis>
        </joint>
 


    </model>
</sdf>
