<sdf version="1.6">
    <model name="x3">
        <pose>0 0 0.1 0 0 0</pose>
        <link name="X3/base_link">
            <pose frame="">0 0 0 0 0 0</pose>
            <inertial>
                <pose frame="">0.0 0.0 0 0 -0 0</pose>
                <mass>0.596</mass>
                <inertia>
                    <ixx>0.001744744189</ixx>
                    <ixy>0</ixy>
                    <ixz>0</ixz>
                    <iyy>0.001400539551</iyy>
                    <iyz>0</iyz>
                    <izz>0.002782410904</izz>
                </inertia>
            </inertial>
            <collision name="X3/base_link_inertia_collision">
                <pose frame="">0 0 0 0 0.0 0</pose>
                <geometry>
                    <box>
                        <size>0.03 0.03 0.03</size>
                    </box>
                </geometry>
            </collision>

            <visual name="X3/base_link_inertia_visual">
                <pose frame="">0 0 0 0 0.0 0</pose>
                <geometry>
                    <box>
                        <size>0.03 0.03 0.03</size>
                    </box>
                </geometry>
            </visual>
            <sensor name="imu_sensor" type="imu">
                <always_on>true</always_on>
                <update_rate>1000</update_rate>
                <pose>0 0 0 0 0 0</pose>
                <imu>
                    <angular_velocity>
                        <x>true</x>
                        <y>true</y>
                        <z>true</z>
                    </angular_velocity>
                    <linear_acceleration>
                        <x>true</x>
                        <y>true</y>
                        <z>true</z>
                    </linear_acceleration>
                </imu>
            </sensor>
        </link>


        <link name="X3/rotor_0">
            <pose frame="X3/base_link">-0.0865 -0.073 0 0 0 0</pose>
            <inertial>
                <pose frame="">0 0 0 0 -0 0</pose>
                <mass>0.01</mass>
                <inertia>
                    <ixx>9.75e-08</ixx>
                    <ixy>0</ixy>
                    <ixz>0</ixz>
                    <iyy>4.17041e-06</iyy>
                    <iyz>0</iyz>
                    <izz>4.26041e-06</izz>
                </inertia>
            </inertial>
        
            <visual name="X3/rotor_0_visual">
                <pose frame="">0 0 0 0 -0 0</pose>
                <geometry>
                    <mesh>
                        <scale>0.1 0.1 0.1</scale>
                        <uri>https://fuel.gazebosim.org/1.0/openrobotics/models/x3 uav/4/files/meshes/propeller_ccw.dae</uri>
                    </mesh>
                </geometry>
                <material>
                    <script>
                        <name>Gazebo/Blue</name>
                        <uri>file://media/materials/scripts/gazebo.material</uri>
                    </script>
                </material>
            </visual>
            <gravity>1</gravity>
            <velocity_decay/>
        </link>
        <joint name="X3/rotor_0_joint" type="revolute">
            <child>X3/rotor_0</child>
            <parent>X3/base_link</parent>
            <axis>
                <xyz>0 0 1</xyz>
                <limit>
                    <lower>-1e+16</lower>
                    <upper>1e+16</upper>
                </limit>
                <dynamics>
                    <spring_reference>0</spring_reference>
                    <spring_stiffness>0</spring_stiffness>
                </dynamics>
                <use_parent_model_frame>1</use_parent_model_frame>
            </axis>
        </joint>



        <link name="X3/rotor_1">
            <pose frame="X3/base_link">0.0865 -0.073 0 0 0 0</pose>
            <inertial>
                <pose frame="">0 0 0 0 -0 0</pose>
                <mass>0.01</mass>
                <inertia>
                    <ixx>9.75e-08</ixx>
                    <ixy>0</ixy>
                    <ixz>0</ixz>
                    <iyy>4.17041e-06</iyy>
                    <iyz>0</iyz>
                    <izz>4.26041e-06</izz>
                </inertia>
            </inertial>
           
            <visual name="X3/rotor_1_visual">
                <pose frame="">0 0 0 0 -0 0</pose>
                <geometry>
                    <mesh>
                        <scale>0.1 0.1 0.1</scale>
                        <uri>https://fuel.gazebosim.org/1.0/openrobotics/models/x3 uav/4/files/meshes/propeller_ccw.dae</uri>
                    </mesh>
                </geometry>
                <material>
                    <script>
                        <name>Gazebo/Red</name>
                        <uri>file://media/materials/scripts/gazebo.material</uri>
                    </script>
                </material>
            </visual>
            <gravity>1</gravity>
            <velocity_decay/>
        </link>
        <joint name="X3/rotor_1_joint" type="revolute">
            <child>X3/rotor_1</child>
            <parent>X3/base_link</parent>
            <axis>
                <xyz>0 0 1</xyz>
                <limit>
                    <lower>-1e+16</lower>
                    <upper>1e+16</upper>
                </limit>
                <dynamics>
                    <spring_reference>0</spring_reference>
                    <spring_stiffness>0</spring_stiffness>
                </dynamics>
                <use_parent_model_frame>1</use_parent_model_frame>
            </axis>
        </joint>



        <link name="X3/rotor_2">
            <pose frame="X3/base_link">-0.0865 0.073 0 0 0 0</pose>
            <inertial>
                <pose frame="">0 0 0 0 -0 0</pose>
                <mass>0.01</mass>
                <inertia>
                    <ixx>9.75e-08</ixx>
                    <ixy>0</ixy>
                    <ixz>0</ixz>
                    <iyy>4.17041e-06</iyy>
                    <iyz>0</iyz>
                    <izz>4.26041e-06</izz>
                </inertia>
            </inertial>
            
            <visual name="X3/rotor_2_visual">
                <pose frame="">0 0 0 0 -0 0</pose>
                <geometry>
                    <mesh>
                        <scale>0.1 0.1 0.1</scale>
                        <uri>https://fuel.gazebosim.org/1.0/openrobotics/models/x3 uav/4/files/meshes/propeller_cw.dae</uri>
                    </mesh>
                </geometry>
                <material>
                    <script>
                        <name>Gazebo/Blue</name>
                        <uri>file://media/materials/scripts/gazebo.material</uri>
                    </script>
                </material>
            </visual>
            <gravity>1</gravity>
            <velocity_decay/>
        </link>
        <joint name="X3/rotor_2_joint" type="revolute">
            <child>X3/rotor_2</child>
            <parent>X3/base_link</parent>
            <axis>
                <xyz>0 0 1</xyz>
                <limit>
                    <lower>-1e+16</lower>
                    <upper>1e+16</upper>
                </limit>
                <dynamics>
                    <spring_reference>0</spring_reference>
                    <spring_stiffness>0</spring_stiffness>
                </dynamics>
                <use_parent_model_frame>1</use_parent_model_frame>
            </axis>
        </joint>



        <link name="X3/rotor_3">
            <pose frame="X3/base_link">0.0865 0.073 0 0 0 0</pose>
            <inertial>
                <pose frame="">0 0 0 0 -0 0</pose>
                <mass>0.01</mass>
                <inertia>
                    <ixx>9.75e-08</ixx>
                    <ixy>0</ixy>
                    <ixz>0</ixz>
                    <iyy>4.17041e-06</iyy>
                    <iyz>0</iyz>
                    <izz>4.26041e-06</izz>
                </inertia>
            </inertial>
            
            <visual name="X3/rotor_3_visual">
                <pose frame="">0 0 0 0 -0 0</pose>
                <geometry>
                    <mesh>
                        <scale>0.1 0.1 0.1</scale>
                        <uri>https://fuel.gazebosim.org/1.0/openrobotics/models/x3 uav/4/files/meshes/propeller_cw.dae</uri>
                    </mesh>
                </geometry>
                <material>
                    <script>
                        <name>Gazebo/Red</name>
                        <uri>file://media/materials/scripts/gazebo.material</uri>
                    </script>
                </material>
            </visual>
            <gravity>1</gravity>
            <velocity_decay/>
        </link>
        <joint name="X3/rotor_3_joint" type="revolute">
            <child>X3/rotor_3</child>
            <parent>X3/base_link</parent>
            <axis>
                <xyz>0 0 1</xyz>
                <limit>
                    <lower>-1e+16</lower>
                    <upper>1e+16</upper>
                </limit>
                <dynamics>
                    <spring_reference>0</spring_reference>
                    <spring_stiffness>0</spring_stiffness>
                </dynamics>
                <use_parent_model_frame>1</use_parent_model_frame>
            </axis>
        </joint>
        <link name='X3/pendulum'>
            <pose>0 0 0.215 0 0 0</pose>
            <inertial>
                <mass>0.000001</mass>
                <inertia>
                    <ixx>5.3e-8</ixx>
                    <ixy>0</ixy>
                    <ixz>0</ixz>
                    <iyy>5.3e-8</iyy>
                    <iyz>0</iyz>
                    <izz>8.3e-12</izz>
                </inertia>
            </inertial> 
            <gravity>1</gravity>
            <self_collide>0</self_collide>
            <kinematic>1</kinematic>
            <visual name='pendulum_visual'>
                <geometry>
                <cylinder>
                    <radius>0.005</radius>
                    <length>0.4</length>
                </cylinder>
                </geometry>
                <material>
                <lighting>1</lighting>
                <script>
                    <uri>file://media/materials/scripts/gazebo.material</uri>
                    <name>Gazebo/Grey</name>
                </script>
                <ambient>0.3 0.3 0.3 1</ambient>
                <diffuse>0.7 0.7 0.7 1</diffuse>
                <specular>0.01 0.01 0.01 1</specular>
                <emissive>0 0 0 1</emissive>
                <shader type='vertex'>
                    <normal_map>__default__</normal_map>
                </shader>
                </material>
                <cast_shadows>1</cast_shadows>
                <transparency>0</transparency>
            </visual>
            <sensor name="imu_sensor" type="imu">
                <always_on>1</always_on>
                <update_rate>1</update_rate>
                <topic>imu</topic>
                <visualize>true</visualize>
                <pose>0 0 0 0 0 0</pose>
                <imu>
                    <angular_velocity>
                        <x>true</x>
                        <y>true</y>
                        <z>true</z>
                    </angular_velocity>
                    <linear_acceleration>
                        <x>true</x>
                        <y>true</y>
                        <z>true</z>
                    </linear_acceleration>
                </imu>
            </sensor>
            <collision name='collision'>
                <geometry>
                <cylinder>
                    <radius>0.005</radius>
                    <length>0.4</length>
                </cylinder>
                </geometry> 
            </collision>
            </link>

        <joint name='X3/pendulum_pivot' type='revolute'>
            <parent>X3/base_link</parent>
            <child>X3/pendulum</child>
            <pose>0 0 -0.2 0 -0 0</pose>
            <axis>
                <xyz> 1 0 0</xyz>
                <limit>
                <lower>-1.57</lower>
                <upper>1.57</upper>
                <effort>0.0</effort>
                <velocity>1000</velocity>
                </limit>
                <dynamics>
                <spring_reference>0</spring_reference>
                <spring_stiffness>0</spring_stiffness>
                <damping>0.0</damping>
                <friction>0.0</friction>
                </dynamics>
            </axis>
            </joint>
        
        
    </model>
</sdf>
